2023-03-09 11:58:44,564 DEBUG A DEBUG Message
2023-03-09 11:58:44,564 INFO An INFO
2023-03-09 11:58:44,565 WARNING A WARNING
2023-03-09 11:58:44,565 ERROR An ERROR
2023-03-09 11:58:44,565 CRITICAL A message of CRITICAL severity
2023-03-09 11:58:44,577 DEBUG Starting new HTTPS connection (1): api.telegram.org:443
2023-03-09 11:58:44,816 DEBUG https://api.telegram.org:443 "GET /bot5941676589:AAExTrhG3aZCkG13obkHyzPE-Z8F5NTxq_A/getMe HTTP/1.1" 200 196
2023-03-09 11:58:44,821 DEBUG Starting new HTTPS connection (1): api.telegram.org:443
2023-03-09 11:58:48,875 DEBUG https://api.telegram.org:443 "GET /bot5941676589:AAExTrhG3aZCkG13obkHyzPE-Z8F5NTxq_A/getUpdates?offset=1&timeout=20 HTTP/1.1" 409 143
2023-03-09 11:58:48,882 ERROR Threaded polling exception: A request to the Telegram API was unsuccessful. Error code: 409. Description: Conflict: terminated by other getUpdates request; make sure that only one bot instance is running
2023-03-09 11:58:48,883 ERROR Exception traceback:
Traceback (most recent call last):
  File "C:\Users\g.virbitskas\AppData\Local\Programs\Python\AEtelebot\lib\site-packages\telebot\__init__.py", line 1073, in __threaded_polling
    polling_thread.raise_exceptions()
  File "C:\Users\g.virbitskas\AppData\Local\Programs\Python\AEtelebot\lib\site-packages\telebot\util.py", line 109, in raise_exceptions
    raise self.exception_info
  File "C:\Users\g.virbitskas\AppData\Local\Programs\Python\AEtelebot\lib\site-packages\telebot\util.py", line 91, in run
    task(*args, **kwargs)
  File "C:\Users\g.virbitskas\AppData\Local\Programs\Python\AEtelebot\lib\site-packages\telebot\__init__.py", line 649, in __retrieve_updates
    updates = self.get_updates(offset=(self.last_update_id + 1),
  File "C:\Users\g.virbitskas\AppData\Local\Programs\Python\AEtelebot\lib\site-packages\telebot\__init__.py", line 623, in get_updates
    json_updates = apihelper.get_updates(self.token, offset, limit, timeout, allowed_updates, long_polling_timeout)
  File "C:\Users\g.virbitskas\AppData\Local\Programs\Python\AEtelebot\lib\site-packages\telebot\apihelper.py", line 321, in get_updates
    return _make_request(token, method_url, params=payload)
  File "C:\Users\g.virbitskas\AppData\Local\Programs\Python\AEtelebot\lib\site-packages\telebot\apihelper.py", line 162, in _make_request
    json_result = _check_result(method_name, result)
  File "C:\Users\g.virbitskas\AppData\Local\Programs\Python\AEtelebot\lib\site-packages\telebot\apihelper.py", line 189, in _check_result
    raise ApiTelegramException(method_name, result, result_json)
telebot.apihelper.ApiTelegramException: A request to the Telegram API was unsuccessful. Error code: 409. Description: Conflict: terminated by other getUpdates request; make sure that only one bot instance is running

2023-03-09 11:58:53,314 DEBUG https://api.telegram.org:443 "GET /bot5941676589:AAExTrhG3aZCkG13obkHyzPE-Z8F5NTxq_A/getUpdates?offset=1&timeout=20 HTTP/1.1" 409 143
2023-03-09 11:58:53,316 ERROR Threaded polling exception: A request to the Telegram API was unsuccessful. Error code: 409. Description: Conflict: terminated by other getUpdates request; make sure that only one bot instance is running
2023-03-09 11:58:53,317 ERROR Exception traceback:
Traceback (most recent call last):
  File "C:\Users\g.virbitskas\AppData\Local\Programs\Python\AEtelebot\lib\site-packages\telebot\__init__.py", line 1073, in __threaded_polling
    polling_thread.raise_exceptions()
  File "C:\Users\g.virbitskas\AppData\Local\Programs\Python\AEtelebot\lib\site-packages\telebot\util.py", line 109, in raise_exceptions
    raise self.exception_info
  File "C:\Users\g.virbitskas\AppData\Local\Programs\Python\AEtelebot\lib\site-packages\telebot\util.py", line 91, in run
    task(*args, **kwargs)
  File "C:\Users\g.virbitskas\AppData\Local\Programs\Python\AEtelebot\lib\site-packages\telebot\__init__.py", line 649, in __retrieve_updates
    updates = self.get_updates(offset=(self.last_update_id + 1),
  File "C:\Users\g.virbitskas\AppData\Local\Programs\Python\AEtelebot\lib\site-packages\telebot\__init__.py", line 623, in get_updates
    json_updates = apihelper.get_updates(self.token, offset, limit, timeout, allowed_updates, long_polling_timeout)
  File "C:\Users\g.virbitskas\AppData\Local\Programs\Python\AEtelebot\lib\site-packages\telebot\apihelper.py", line 321, in get_updates
    return _make_request(token, method_url, params=payload)
  File "C:\Users\g.virbitskas\AppData\Local\Programs\Python\AEtelebot\lib\site-packages\telebot\apihelper.py", line 162, in _make_request
    json_result = _check_result(method_name, result)
  File "C:\Users\g.virbitskas\AppData\Local\Programs\Python\AEtelebot\lib\site-packages\telebot\apihelper.py", line 189, in _check_result
    raise ApiTelegramException(method_name, result, result_json)
telebot.apihelper.ApiTelegramException: A request to the Telegram API was unsuccessful. Error code: 409. Description: Conflict: terminated by other getUpdates request; make sure that only one bot instance is running

2023-03-09 11:58:58,249 DEBUG https://api.telegram.org:443 "GET /bot5941676589:AAExTrhG3aZCkG13obkHyzPE-Z8F5NTxq_A/getUpdates?offset=1&timeout=20 HTTP/1.1" 409 143
2023-03-09 11:58:58,251 ERROR Threaded polling exception: A request to the Telegram API was unsuccessful. Error code: 409. Description: Conflict: terminated by other getUpdates request; make sure that only one bot instance is running
2023-03-09 11:58:58,252 ERROR Exception traceback:
Traceback (most recent call last):
  File "C:\Users\g.virbitskas\AppData\Local\Programs\Python\AEtelebot\lib\site-packages\telebot\__init__.py", line 1073, in __threaded_polling
    polling_thread.raise_exceptions()
  File "C:\Users\g.virbitskas\AppData\Local\Programs\Python\AEtelebot\lib\site-packages\telebot\util.py", line 109, in raise_exceptions
    raise self.exception_info
  File "C:\Users\g.virbitskas\AppData\Local\Programs\Python\AEtelebot\lib\site-packages\telebot\util.py", line 91, in run
    task(*args, **kwargs)
  File "C:\Users\g.virbitskas\AppData\Local\Programs\Python\AEtelebot\lib\site-packages\telebot\__init__.py", line 649, in __retrieve_updates
    updates = self.get_updates(offset=(self.last_update_id + 1),
  File "C:\Users\g.virbitskas\AppData\Local\Programs\Python\AEtelebot\lib\site-packages\telebot\__init__.py", line 623, in get_updates
    json_updates = apihelper.get_updates(self.token, offset, limit, timeout, allowed_updates, long_polling_timeout)
  File "C:\Users\g.virbitskas\AppData\Local\Programs\Python\AEtelebot\lib\site-packages\telebot\apihelper.py", line 321, in get_updates
    return _make_request(token, method_url, params=payload)
  File "C:\Users\g.virbitskas\AppData\Local\Programs\Python\AEtelebot\lib\site-packages\telebot\apihelper.py", line 162, in _make_request
    json_result = _check_result(method_name, result)
  File "C:\Users\g.virbitskas\AppData\Local\Programs\Python\AEtelebot\lib\site-packages\telebot\apihelper.py", line 189, in _check_result
    raise ApiTelegramException(method_name, result, result_json)
telebot.apihelper.ApiTelegramException: A request to the Telegram API was unsuccessful. Error code: 409. Description: Conflict: terminated by other getUpdates request; make sure that only one bot instance is running

2023-03-09 11:59:04,721 DEBUG https://api.telegram.org:443 "GET /bot5941676589:AAExTrhG3aZCkG13obkHyzPE-Z8F5NTxq_A/getUpdates?offset=1&timeout=20 HTTP/1.1" 409 143
2023-03-09 11:59:04,723 ERROR Threaded polling exception: A request to the Telegram API was unsuccessful. Error code: 409. Description: Conflict: terminated by other getUpdates request; make sure that only one bot instance is running
2023-03-09 11:59:04,724 ERROR Exception traceback:
Traceback (most recent call last):
  File "C:\Users\g.virbitskas\AppData\Local\Programs\Python\AEtelebot\lib\site-packages\telebot\__init__.py", line 1073, in __threaded_polling
    polling_thread.raise_exceptions()
  File "C:\Users\g.virbitskas\AppData\Local\Programs\Python\AEtelebot\lib\site-packages\telebot\util.py", line 109, in raise_exceptions
    raise self.exception_info
  File "C:\Users\g.virbitskas\AppData\Local\Programs\Python\AEtelebot\lib\site-packages\telebot\util.py", line 91, in run
    task(*args, **kwargs)
  File "C:\Users\g.virbitskas\AppData\Local\Programs\Python\AEtelebot\lib\site-packages\telebot\__init__.py", line 649, in __retrieve_updates
    updates = self.get_updates(offset=(self.last_update_id + 1),
  File "C:\Users\g.virbitskas\AppData\Local\Programs\Python\AEtelebot\lib\site-packages\telebot\__init__.py", line 623, in get_updates
    json_updates = apihelper.get_updates(self.token, offset, limit, timeout, allowed_updates, long_polling_timeout)
  File "C:\Users\g.virbitskas\AppData\Local\Programs\Python\AEtelebot\lib\site-packages\telebot\apihelper.py", line 321, in get_updates
    return _make_request(token, method_url, params=payload)
  File "C:\Users\g.virbitskas\AppData\Local\Programs\Python\AEtelebot\lib\site-packages\telebot\apihelper.py", line 162, in _make_request
    json_result = _check_result(method_name, result)
  File "C:\Users\g.virbitskas\AppData\Local\Programs\Python\AEtelebot\lib\site-packages\telebot\apihelper.py", line 189, in _check_result
    raise ApiTelegramException(method_name, result, result_json)
telebot.apihelper.ApiTelegramException: A request to the Telegram API was unsuccessful. Error code: 409. Description: Conflict: terminated by other getUpdates request; make sure that only one bot instance is running

2023-03-09 11:59:14,059 DEBUG https://api.telegram.org:443 "GET /bot5941676589:AAExTrhG3aZCkG13obkHyzPE-Z8F5NTxq_A/getUpdates?offset=1&timeout=20 HTTP/1.1" 409 143
2023-03-09 11:59:14,063 ERROR Threaded polling exception: A request to the Telegram API was unsuccessful. Error code: 409. Description: Conflict: terminated by other getUpdates request; make sure that only one bot instance is running
2023-03-09 11:59:14,066 ERROR Exception traceback:
Traceback (most recent call last):
  File "C:\Users\g.virbitskas\AppData\Local\Programs\Python\AEtelebot\lib\site-packages\telebot\__init__.py", line 1073, in __threaded_polling
    polling_thread.raise_exceptions()
  File "C:\Users\g.virbitskas\AppData\Local\Programs\Python\AEtelebot\lib\site-packages\telebot\util.py", line 109, in raise_exceptions
    raise self.exception_info
  File "C:\Users\g.virbitskas\AppData\Local\Programs\Python\AEtelebot\lib\site-packages\telebot\util.py", line 91, in run
    task(*args, **kwargs)
  File "C:\Users\g.virbitskas\AppData\Local\Programs\Python\AEtelebot\lib\site-packages\telebot\__init__.py", line 649, in __retrieve_updates
    updates = self.get_updates(offset=(self.last_update_id + 1),
  File "C:\Users\g.virbitskas\AppData\Local\Programs\Python\AEtelebot\lib\site-packages\telebot\__init__.py", line 623, in get_updates
    json_updates = apihelper.get_updates(self.token, offset, limit, timeout, allowed_updates, long_polling_timeout)
  File "C:\Users\g.virbitskas\AppData\Local\Programs\Python\AEtelebot\lib\site-packages\telebot\apihelper.py", line 321, in get_updates
    return _make_request(token, method_url, params=payload)
  File "C:\Users\g.virbitskas\AppData\Local\Programs\Python\AEtelebot\lib\site-packages\telebot\apihelper.py", line 162, in _make_request
    json_result = _check_result(method_name, result)
  File "C:\Users\g.virbitskas\AppData\Local\Programs\Python\AEtelebot\lib\site-packages\telebot\apihelper.py", line 189, in _check_result
    raise ApiTelegramException(method_name, result, result_json)
telebot.apihelper.ApiTelegramException: A request to the Telegram API was unsuccessful. Error code: 409. Description: Conflict: terminated by other getUpdates request; make sure that only one bot instance is running

2023-03-09 11:59:26,225 DEBUG https://api.telegram.org:443 "GET /bot5941676589:AAExTrhG3aZCkG13obkHyzPE-Z8F5NTxq_A/getUpdates?offset=1&timeout=20 HTTP/1.1" 409 143
2023-03-09 11:59:26,227 ERROR Threaded polling exception: A request to the Telegram API was unsuccessful. Error code: 409. Description: Conflict: terminated by other getUpdates request; make sure that only one bot instance is running
2023-03-09 11:59:26,229 ERROR Exception traceback:
Traceback (most recent call last):
  File "C:\Users\g.virbitskas\AppData\Local\Programs\Python\AEtelebot\lib\site-packages\telebot\__init__.py", line 1073, in __threaded_polling
    polling_thread.raise_exceptions()
  File "C:\Users\g.virbitskas\AppData\Local\Programs\Python\AEtelebot\lib\site-packages\telebot\util.py", line 109, in raise_exceptions
    raise self.exception_info
  File "C:\Users\g.virbitskas\AppData\Local\Programs\Python\AEtelebot\lib\site-packages\telebot\util.py", line 91, in run
    task(*args, **kwargs)
  File "C:\Users\g.virbitskas\AppData\Local\Programs\Python\AEtelebot\lib\site-packages\telebot\__init__.py", line 649, in __retrieve_updates
    updates = self.get_updates(offset=(self.last_update_id + 1),
  File "C:\Users\g.virbitskas\AppData\Local\Programs\Python\AEtelebot\lib\site-packages\telebot\__init__.py", line 623, in get_updates
    json_updates = apihelper.get_updates(self.token, offset, limit, timeout, allowed_updates, long_polling_timeout)
  File "C:\Users\g.virbitskas\AppData\Local\Programs\Python\AEtelebot\lib\site-packages\telebot\apihelper.py", line 321, in get_updates
    return _make_request(token, method_url, params=payload)
  File "C:\Users\g.virbitskas\AppData\Local\Programs\Python\AEtelebot\lib\site-packages\telebot\apihelper.py", line 162, in _make_request
    json_result = _check_result(method_name, result)
  File "C:\Users\g.virbitskas\AppData\Local\Programs\Python\AEtelebot\lib\site-packages\telebot\apihelper.py", line 189, in _check_result
    raise ApiTelegramException(method_name, result, result_json)
telebot.apihelper.ApiTelegramException: A request to the Telegram API was unsuccessful. Error code: 409. Description: Conflict: terminated by other getUpdates request; make sure that only one bot instance is running

2023-03-09 11:59:50,550 DEBUG https://api.telegram.org:443 "GET /bot5941676589:AAExTrhG3aZCkG13obkHyzPE-Z8F5NTxq_A/getUpdates?offset=1&timeout=20 HTTP/1.1" 409 143
2023-03-09 11:59:50,554 ERROR Threaded polling exception: A request to the Telegram API was unsuccessful. Error code: 409. Description: Conflict: terminated by other getUpdates request; make sure that only one bot instance is running
2023-03-09 11:59:50,557 ERROR Exception traceback:
Traceback (most recent call last):
  File "C:\Users\g.virbitskas\AppData\Local\Programs\Python\AEtelebot\lib\site-packages\telebot\__init__.py", line 1073, in __threaded_polling
    polling_thread.raise_exceptions()
  File "C:\Users\g.virbitskas\AppData\Local\Programs\Python\AEtelebot\lib\site-packages\telebot\util.py", line 109, in raise_exceptions
    raise self.exception_info
  File "C:\Users\g.virbitskas\AppData\Local\Programs\Python\AEtelebot\lib\site-packages\telebot\util.py", line 91, in run
    task(*args, **kwargs)
  File "C:\Users\g.virbitskas\AppData\Local\Programs\Python\AEtelebot\lib\site-packages\telebot\__init__.py", line 649, in __retrieve_updates
    updates = self.get_updates(offset=(self.last_update_id + 1),
  File "C:\Users\g.virbitskas\AppData\Local\Programs\Python\AEtelebot\lib\site-packages\telebot\__init__.py", line 623, in get_updates
    json_updates = apihelper.get_updates(self.token, offset, limit, timeout, allowed_updates, long_polling_timeout)
  File "C:\Users\g.virbitskas\AppData\Local\Programs\Python\AEtelebot\lib\site-packages\telebot\apihelper.py", line 321, in get_updates
    return _make_request(token, method_url, params=payload)
  File "C:\Users\g.virbitskas\AppData\Local\Programs\Python\AEtelebot\lib\site-packages\telebot\apihelper.py", line 162, in _make_request
    json_result = _check_result(method_name, result)
  File "C:\Users\g.virbitskas\AppData\Local\Programs\Python\AEtelebot\lib\site-packages\telebot\apihelper.py", line 189, in _check_result
    raise ApiTelegramException(method_name, result, result_json)
telebot.apihelper.ApiTelegramException: A request to the Telegram API was unsuccessful. Error code: 409. Description: Conflict: terminated by other getUpdates request; make sure that only one bot instance is running

2023-03-09 12:00:27,144 DEBUG https://api.telegram.org:443 "GET /bot5941676589:AAExTrhG3aZCkG13obkHyzPE-Z8F5NTxq_A/getUpdates?offset=1&timeout=20 HTTP/1.1" 200 23
2023-03-09 12:00:39,008 DEBUG https://api.telegram.org:443 "GET /bot5941676589:AAExTrhG3aZCkG13obkHyzPE-Z8F5NTxq_A/getUpdates?offset=1&timeout=20 HTTP/1.1" 409 143
2023-03-09 12:00:39,009 ERROR Threaded polling exception: A request to the Telegram API was unsuccessful. Error code: 409. Description: Conflict: terminated by other getUpdates request; make sure that only one bot instance is running
2023-03-09 12:00:39,010 ERROR Exception traceback:
Traceback (most recent call last):
  File "C:\Users\g.virbitskas\AppData\Local\Programs\Python\AEtelebot\lib\site-packages\telebot\__init__.py", line 1073, in __threaded_polling
    polling_thread.raise_exceptions()
  File "C:\Users\g.virbitskas\AppData\Local\Programs\Python\AEtelebot\lib\site-packages\telebot\util.py", line 109, in raise_exceptions
    raise self.exception_info
  File "C:\Users\g.virbitskas\AppData\Local\Programs\Python\AEtelebot\lib\site-packages\telebot\util.py", line 91, in run
    task(*args, **kwargs)
  File "C:\Users\g.virbitskas\AppData\Local\Programs\Python\AEtelebot\lib\site-packages\telebot\__init__.py", line 649, in __retrieve_updates
    updates = self.get_updates(offset=(self.last_update_id + 1),
  File "C:\Users\g.virbitskas\AppData\Local\Programs\Python\AEtelebot\lib\site-packages\telebot\__init__.py", line 623, in get_updates
    json_updates = apihelper.get_updates(self.token, offset, limit, timeout, allowed_updates, long_polling_timeout)
  File "C:\Users\g.virbitskas\AppData\Local\Programs\Python\AEtelebot\lib\site-packages\telebot\apihelper.py", line 321, in get_updates
    return _make_request(token, method_url, params=payload)
  File "C:\Users\g.virbitskas\AppData\Local\Programs\Python\AEtelebot\lib\site-packages\telebot\apihelper.py", line 162, in _make_request
    json_result = _check_result(method_name, result)
  File "C:\Users\g.virbitskas\AppData\Local\Programs\Python\AEtelebot\lib\site-packages\telebot\apihelper.py", line 189, in _check_result
    raise ApiTelegramException(method_name, result, result_json)
telebot.apihelper.ApiTelegramException: A request to th2023-03-09 12:00:42,627 DEBUG https://api.telegram.org:443 "GET /bot5941676589:AAExTrhG3aZCkG13obkHyzPE-Z8F5NTxq_A/getUpdates?offset=1&timeout=20 HTTP/1.1" 409 1432023-03-09 12:00:59,401 DEBUG https://api.telegram.org:443 "GET /bot5941676589:AAExTrhG3aZCkG13obkHyzPE-Z8F5NTxq_A/getUpdates?offset=1&timeout=20 HTTP/1.1" 200 23
2023-03-09 12:01:19,743 DEBUG https://api.telegram.org:443 "GET /bot5941676589:AAExTrhG3aZCkG13obkHyzPE-Z8F5NTxq_A/getUpdates?offset=1&timeout=20 HTTP/1.1" 200 23
2023-03-09 12:01:40,007 DEBUG https://api.telegram.org:443 "GET /bot5941676589:AAExTrhG3aZCkG13obkHyzPE-Z8F5NTxq_A/getUpdates?offset=1&timeout=20 HTTP/1.1" 200 23
2023-03-09 12:01:42,874 DEBUG https://api.telegram.org:443 "GET /bot5941676589:AAExTrhG3aZCkG13obkHyzPE-Z8F5NTxq_A/getUpdates?offset=1&timeout=20 HTTP/1.1" 409 143
2023-03-09 12:01:42,876 ERROR Threaded polling exception: A request to the Telegram API was unsuccessful. Error code: 409. Description: Conflict: terminated by other getUpdates request; make sure that only one bot instance is running
2023-03-09 12:01:42,878 ERROR Exception traceback:
Traceback (most recent call last):
  File "C:\Users\g.virbitskas\AppData\Local\Programs\Python\AEtelebot\lib\site-packages\telebot\__init__.py", line 1073, in __threaded_polling
    polling_thread.raise_exceptions()
  File "C:\Users\g.virbitskas\AppData\Local\Programs\Python\AEtelebot\lib\site-packages\telebot\util.py", line 109, in raise_exceptions
    raise self.exception_info
  File "C:\Users\g.virbitskas\AppData\Local\Programs\Python\AEtelebot\lib\site-packages\telebot\util.py", line 91, in run
    task(*args, **kwargs)
  File "C:\Users\g.virbitskas\AppData\Local\Programs\Python\AEtelebot\lib\site-packages\telebot\__init__.py", line 649, in __retrieve_updates
    updates = self.get_updates(offset=(self.last_update_id + 1),
  File "C:\Users\g.virbitskas\AppData\Local\Programs\Python\AEtelebot\lib\site-packages\telebot\__init__.py", line 623, in get_updates
    json_updates = apihelper.get_updates(self.token, offset, limit, timeout, allowed_updates, long_polling_timeout)
  File "C:\Users\g.virbitskas\AppData\Local\Programs\Python\AEtelebot\lib\site-packages\telebot\apihelper.py", line 321, in get_updates
    return _make_reque2023-03-09 12:01:46,455 DEBUG https://api.telegram.org:443 "GET /bot5941676589:AAExTrhG3aZCkG13obkHyzPE-Z8F5NTxq_A/getUpdates?offset=1&timeout=20 HTTP/1.1" 409 143
2023-03-09 12:01:46,457 ERROR Threaded polling exception: A request to the Telegram API was unsuccessful. Error code: 409. Description: Conflict: terminated by other getUpdates request; make sure that only one bot instance is running
2023-03-09 12:01:46,458 ERROR Exception traceback:
Traceback (most recent call last):
  File "C:\Users\g.virbitskas\AppData\Local\Programs\Python\AEtelebot\lib\site-packages\telebot\__init__.py", line 1073, in __threaded_polling
    polling_thread.raise2023-03-09 12:02:03,647 DEBUG https://api.telegram.org:443 "GET /bot5941676589:AAExTrhG3aZCkG13obkHyzPE-Z8F5NTxq_A/getUpdates?offset=1&timeout=20 HTTP/1.1" 200 23
2023-03-09 12:02:23,716 DEBUG https://api.telegram.org:443 "GET /bot5941676589:AAExTrhG3aZCkG13obkHyzPE-Z8F5NTxq_A/getUpdates?offset=1&timeout=20 HTTP/1.1" 200 23
2023-03-09 12:02:44,069 DEBUG https://api.telegram.org:443 "GET /bot5941676589:AAExTrhG3aZCkG13obkHyzPE-Z8F5NTxq_A/getUpdates?offset=1&timeout=20 HTTP/1.1" 200 23
2023-03-09 12:02:46,769 DEBUG https://api.telegram.org:443 "GET /bot5941676589:AAExTrhG3aZCkG13obkHyzPE-Z8F5NTxq_A/getUpdates?offset=1&timeout=20 HTTP/1.1" 409 143
2023-03-09 12:02:46,772 ERROR Threaded polling exception: A request to the Telegram API was unsuccessful. Error code: 409. Description: Conflict: terminated by other getUpdates request; make sure that only one bot instance is running
2023-03-09 12:02:46,773 ERROR Exception traceback:
Traceback (most recent call last):
  File "C:\Users\g.virbitskas\AppData\Local\Programs\Python\AEtelebot\lib\site-packages\telebot\__init__.py", line 1073, in __threaded_polling
    polling_thread.raise_exceptions()
  File "C:\Users\g.virbitskas\AppData\Local\Programs\Python\AEtelebot\lib\site-packages\telebot\util.py", line 109, in raise_exceptions
    raise self.exception_info
  File "C:\Users\g.virbitskas\AppData\Local\Programs\Python\AEtelebot\lib\site-packages\telebot\util.py", line 91, in run
    task(*args, **kwargs)
  File "C:\Users\g.virbitskas\AppData\Local\Programs\Python\AEtelebot\lib\site-packages\telebot\__init__.py", line 649, in __retr2023-03-09 12:02:50,107 DEBUG https://api.telegram.org:443 "GET /bot5941676589:AAExTrhG3aZCkG13obkHyzPE-Z8F5NTxq_A/getUpdates?offset=1&timeout=20 HTTP/1.1" 409 143
2023-03-09 12:02:50,108 ERROR Threaded polling exception: A request to the Telegram API was unsuccessful. Error code: 409. Description: Conflict: terminated by other getUpdates request; make sure that only one bot instance is running
2023-03-09 12:02:50,111 ERROR Exception traceback:
Traceback (most recent call last):
  File "C:\Users\g.virbitskas\AppData\Local\Programs\Python\AEtelebot\lib\site-packages\telebot\__init__.py", line 1073, in __threaded_polling
    polling_thread.raise_exceptions()
  File "C:\Users\g.virbitskas\AppData\Local\Programs\Python\AEtelebot\lib\site-packages\telebot\util.py", line 109, in raise_exceptions
    raise self.exception_info
  File "C:\Users\g.virbitskas\AppData\Local\Programs\Python\AEtelebot\lib\site-packages\telebot\util.py", line 91, in run
    task(*args, **kwargs)
  File "C:\Users\g.virbitskas\AppData\Local\Programs\Python\AEtelebot\lib\site-packages\telebot\__init__.py", line 649, in __retrieve_updates
    updates = se2023-03-09 12:03:07,295 DEBUG https://api.telegram.org:443 "GET /bot5941676589:AAExTrhG3aZCkG13obkHyzPE-Z8F5NTxq_A/getUpdates?offset=1&timeout=20 HTTP/1.1" 200 23
2023-03-09 12:03:27,362 DEBUG https://api.telegram.org:443 "GET /bot5941676589:AAExTrhG3aZCkG13obkHyzPE-Z8F5NTxq_A/getUpdates?offset=1&timeout=20 HTTP/1.1" 200 23
2023-03-09 12:03:47,432 DEBUG https://api.telegram.org:443 "GET /bot5941676589:AAExTrhG3aZCkG13obkHyzPE-Z8F5NTxq_A/getUpdates?offset=1&timeout=20 HTTP/1.1" 200 23
2023-03-09 12:03:50,195 DEBUG https://api.telegram.org:443 "GET /bot5941676589:AAExTrhG3aZCkG13obkHyzPE-Z8F5NTxq_A/getUpdates?offset=1&timeout=20 HTTP/1.1" 409 143
2023-03-09 12:03:50,199 ERROR Threaded polling exception: A request to the Telegram API was unsuccessful. Error code: 409. Description: Conflict: terminated by other getUpdates request; make sure that only one bot instance is running
2023-03-09 12:03:50,200 ERROR Exception traceback:
Traceback (most recent call last):
  File "C:\Users\g.virbitskas\AppData\Local\Programs\Python\AEtelebot\lib\site-packages\telebot\__init__.py", line 1073, in __threaded_pol2023-03-09 12:03:53,526 DEBUG https://api.telegram.org:443 "GET /bot5941676589:AAExTrhG3aZCkG13obkHyzPE-Z8F5NTxq_A/getUpdates?offset=1&timeout=20 HTTP/1.1" 409 143
2023-03-09 12:03:53,528 ERROR Threaded polling exception: A request to the Telegram API was unsuccessful. Error code: 409. Description: Conflict: terminated by other getUpdates request; make sure that only one bot instance is running
2023-03-09 12:03:53,529 ERROR Exception traceback:
Traceback (most recent call last):
  File "C:\Users\g.virbitskas\AppData\Local\Programs\Python\AEtelebot\lib\site-packages\telebot\__init__.py", line 1073, in __threaded_polling
    polling_thread.raise_exceptions()
  File "C:\Users\g.virbitskas\AppData\Local\Programs\Python\AEtelebot\lib\site-packages\telebot\util.py", line 109, in raise_exceptions
    raise self.exception_info
  File "C:\Users\g.virbitskas\AppData\Local\Programs\Python\AEtelebot\lib\site-packages\telebot\util.py", line 91, in run
    task(*args, **kwargs)
  File "C:\Users\g.virbitskas\AppData\Local\Programs\Python\AEtelebot\lib\site-packages\telebot\__init__.py", line 649, in __retrieve_updates
    updates = self.get_updates(offset=(self.last_update_id + 1),
  File "C:\Users\g.virbitskas\AppData\Local\Programs\Python\AEtelebot\lib\site-packages\telebot\__init__.py", line 623, in get_updates
    json_updates = apihelper.get_updates(self.token, offset, limit, timeout, allowed_updates, long_polling_timeout)
  File "C:\Users\g.virbitskas\AppData\Local\Programs\Python\AEtelebot\lib\site-packages\telebot\apihelper.py", line 321, in get_updates
    return _make_request(token, method_url, params=p2023-03-09 12:04:10,526 DEBUG https://api.telegram.org:443 "GET /bot5941676589:AAExTrhG3aZCkG13obkHyzPE-Z8F5NTxq_A/getUpdates?offset=1&timeout=20 HTTP/1.1" 200 23
2023-03-09 12:04:30,599 DEBUG https://api.telegram.org:443 "GET /bot5941676589:AAExTrhG3aZCkG13obkHyzPE-Z8F5NTxq_A/getUpdates?offset=1&timeout=20 HTTP/1.1" 200 23
2023-03-09 12:04:50,668 DEBUG https://api.telegram.org:443 "GET /bot5941676589:AAExTrhG3aZCkG13obkHyzPE-Z8F5NTxq_A/getUpdates?offset=1&timeout=20 HTTP/1.1" 200 23
2023-03-09 12:04:53,607 DEBUG https://api.telegram.org:443 "GET /bot5941676589:AAExTrhG3aZCkG13obkHyzPE-Z8F5NTxq_A/getUpdates?offset=12023-03-09 12:04:56,962 DEBUG https://api.telegram.org:443 "GET /bot5941676589:AAExTrhG3aZCkG13obkHyzPE-Z8F5NTxq_A/getUpdates?offset=1&timeout=20 HTTP/1.1" 409 143
2023-03-09 12:04:56,964 ERROR Threaded polling exception: A request to the Telegram API was unsuccessful. Error code: 409. Description: Conflict: terminated by other getUpdates request; make sure that only one bot instance is running
2023-03-09 12:04:56,965 ERROR Exception traceback:
Traceback (most recent call last):
  File "C:\Users\g.virbitskas\AppData\Local\Programs\Python\AEtelebot\lib\site-packages\telebot\__init__.py", line 1073, in __threaded_polling
    polling_thread.raise_exceptions()
  File "C:\Users\g.virbitskas\AppData\Local\Programs\Python\AEtelebot\lib\site-packages\telebot\util.py", line 109, in raise_exceptions
    raise self.exception_info
  File "C:\Users\g.virbitskas\AppData\Local\Programs\Python\AEtelebot\lib\site-packages\telebot\util.py", line 91, in run
    task(*args, **kwargs)
  File "C:\Users\g.virbitskas\AppData\Local\Programs\Python\AEtelebot\lib\site-packages\telebot\__init__.py", line 649, in __retrieve_updates
    updates = self.get_updates(offset=(self.last_update_id + 1),
  File "C:\Users\g.virbitskas\AppData\Local\Programs\Python\AEtelebot\lib\site-packages\telebot\__init__.py", line 623, in get_updates
    json_updates = apihelper.get_updates(self.token, offset, limit, timeout, allowed_updates, long_polling_timeout)
  File "C:\Users\g.virbitskas\AppData\Local\Programs\Python\AEtelebot\lib\site-packages\telebot\apihelper.py", line 321, in get_updates
    return _make_request(token, method_url, params=payload)
  File "C:\Users\g.virbitskas\AppData\Local\Programs\Python\AEtelebot\lib\site-packages\telebot\apihelper.py", line 162, in _make_request
    json_result = _check_result(method_name, result)
  File "C:\Users\g.virbitskas\AppData\Local\Programs\Python\AEtelebot\lib\site-packages\telebot\apihelper.py", line 189, in _check_result
    raise ApiTelegramException(method_name, result, result_json)
telebot.apihelper.ApiTelegramException: A request to the Telegram API was unsuccessfu2023-03-09 12:05:13,949 DEBUG https://api.telegram.org:443 "GET /bot5941676589:AAExTrhG3aZCkG13obkHyzPE-Z8F5NTxq_A/getUpdates?offset=1&timeout=20 HTTP/1.1" 200 23
2023-03-09 12:05:34,016 DEBUG https://api.telegram.org:443 "GET /bot5941676589:AAExTrhG3aZCkG13obkHyzPE-Z8F5NTxq_A/getUpdates?offset=1&timeout=20 HTTP/1.1" 200 23
2023-03-09 12:05:54,109 DEBUG https://api.telegram.org:443 "GET /bot5941676589:AAExTrhG3aZCkG13obkHyzPE-Z8F5NTxq_A/getUpdates?offset=1&timeout=20 HTTP/1.1" 200 23
2023-03-09 12:06:14,176 DEBUG https://api.telegram.org:443 "GET /bot5941676589:AAExTrhG3aZCkG13obkHyzPE-Z8F5NTxq_A/getUpdates?offset=1&timeout=20 HTTP/1.1" 200 23
2023-03-09 12:06:34,275 DEBUG https://api.telegram.org:443 "GET /bot5941676589:AAExTrhG3aZCkG13obkHyzPE-Z8F5NTxq_A/getUpdates?offset=1&timeout=20 HTTP/1.1" 200 23
2023-03-09 12:06:54,391 DEBUG https://api.telegram.org:443 "GET /bot5941676589:AAExTrhG3aZCkG13obkHyzPE-Z8F5NTxq_A/getUpdates?offset=1&timeout=20 HTTP/1.1" 200 23
